Workbook
Name NR_JobTitle: Cleaned_Data!$B$11:$B$444
Name NR_Location: Cleaned_Data!$D$11:$D$444
Name NR_Industry: Cleaned_Data!$E$11:$E$444
Name NR_ExpLevel: Cleaned_Data!$F$11:$F$444
Name NR_WorkMode: Cleaned_Data!$H$11:$H$444
Name NR_SalaryMin: Cleaned_Data!$I$11:$I$444
Name NR_SalaryMax: Cleaned_Data!$J$11:$J$444
Name NR_Skills: Cleaned_Data!$K$11:$K$444
Name NR_AvgSalary: Cleaned_Data!$M$11:$M$444
Name NR_RoleCategory: Cleaned_Data!$P$11:$P$444
Name NR_DupFlag: Cleaned_Data!$Q$11:$Q$444
Name NR_F_Role: Dashboard!$B$4
Name NR_F_Loc: Dashboard!$E$4
Name NR_F_Exp: Dashboard!$H$4
Name NR_F_WM: Dashboard!$K$4
Name NR_F_Ind: Dashboard!$N$4

Sheet Instructions
A1: Job Market Analysis Dashboard
A4: Project Objective
A5: Analyze a real sample of Indian job postings and build an interactive Excel dashboard covering demand by role and location, salary ranges, experience levels, top skills, work mode split, and industry mix — the kind of first analysis a Data Analyst / Business Analyst / MIS Executive is asked to do.
A7: How This Workbook Is Organised
A8: 1. Raw_Data — the original, unprocessed job posting records (intentionally contains a few duplicates, inconsistent spellings, extra spaces and missing values, exactly as raw data usually arrives).
A9: 2. Cleaned_Data — the same data cleaned with formulas (TRIM, PROPER, IF, IFS, SEARCH), plus calculated columns: Average_Salary, Salary_Range, Posting_Month, Job_Role_Category and Duplicate_Flag.
A10: 3. Analysis — pivot-style summary tables built with COUNTIFS / SUMIFS / AVERAGEIFS that answer each business question the dashboard needs.
A11: 4. Dashboard — one-page view with 5 live filter dropdowns, 5 KPI cards and 6 charts, all linked live to the Analysis sheet.
A13: Dataset Note
A14: Records are a real, de-identified sample of job postings collected from a public Indian job-search platform (title, company, location, experience, salary and skills fields), narrowed down to ~420 usable postings for this project. Fields not present in the source (Industry, Experience_Level bucket, Work_Mode, Job_Role_Category) were derived using simple keyword rules so the data could be grouped and charted.
A16: How the Interactive Filters Work
A17: The 5 dropdowns at the top of the Dashboard (Job Role, Location, Experience, Work Mode, Industry) are Data Validation lists pointing at the hidden Lists sheet. Every KPI and summary table formula includes an extra IF(filter="All","*",filter) condition for each dropdown, so a wildcard "*" matches everything when a filter is set to "All", and an exact match narrows the results the moment you pick a specific value — no macros required, just COUNTIFS/AVERAGEIFS reading a cell.
... A23: Data cleaning (TRIM, PROPER, IF/IFS text standardization) • Excel Tables • Sorting & filtering • Data Validation dropdown filters • IF / COUNTIF / COUNTIFS / SUMIFS / AVERAGEIFS • SEARCH & TEXT functions • Calculated columns • Pivot-style summary tables • Native Excel charts (bar, column, doughnut) with custom color coding • KPI cards • Conditional formatting • Clean, colorful one-page dashboard design.

Sheet Raw_Data
A1: Job_ID | B1: Job_Title | C1: Company | D1: Location | E1: Industry | F1: Experience_Level | G1: Employment_Type | H1: Work_Mode | I1: Salary_Min | J1: Salary_Max | K1: Required_Skills | L1: Posting_Date
A2: J0375 | B2: Assistant Highway Maintenance Engineer | C2: Theme Engineering Services | D2: Chennai | E2: Manufacturing & Engineering | F2: Mid Level (3-6 yrs) | G2: Full-time | H2: On-site | I2: 2.5 | J2: 3.5 | K2: inspecting and maintaining, Project Handling, Coordination, Nhai | L2: 45966
A3: J0133 | B3: Site Engineer - Track | C3: Consulting Engineers Group (CEG) | D3: Surat | E3: Real Estate & Construction | F3: Mid Level (3-6 yrs) | G3: Full-time | H3: On-site | I3: 6 | J3: 9.5 | L3: 45966
A4: J0344 | B4: Trainer (9 Positions)- Eletrical / Welder / Fittter / Computer (AMLOH) | C4: Kaamkaaj India | D4: Khanna | E4: IT / Software | F4: Entry Level (0-2 yrs) | G4: Full-time | H4: On-site | I4: 1 | J4: 4 | K4: trainer, welder, computer, teacher | L4: 45970
A5: J0033 | B5: Business Development Manager | C5: Scintilla Kreations | D5: Hyderabad | E5: IT / Software | F5: Mid Level (3-6 yrs) | G5: Full-time | H5: On-site | I5: 4.5 | J5: 6 | K5: Business Development, Business Development And Marketing, Branding And Marketing, It Services Sales | L5: 45966
A6: J0061 | B6: B2B Sales Executive | C6: ANK Solar Energy | D6: Surat | E6: Sales & Business Development | F6: Entry Level (0-2 yrs) | G6: Full-time | H6: On-site | I6: 2.5 | J6: 4.5 | K6: B2B Sales, B2B, B2B Business Development, Business To Business | L6: 45973
A7: J0005 | B7: maintenance engineer | C7: Talent Surge | D7: Pune | E7: Manufacturing & Engineering | F7: Mid Level (3-6 yrs) | G7: Full-time | H7: On-site | I7: 4 | J7: 4.5 | K7: Electrical Maintenance, Pneumatic System, Breakdown Maintenance, Preventive Maintenance | L7: 45970
A8: J0386 | B8: Delivery Excellence - ITIL - SA- Professional | C8: Golden Opportunities | D8: Pune | E8: Other / General Business | F8: Mid Level (3-6 yrs) | G8: Full-time | H8: On-site | K8: ITIL, Delivery Excellence, Program Management, Value stream mapping | L8: 45973
A9: J0255 | B9: Civil Engineer | C9: PRO Hr Complete Solutions | D9: Jaipur | E9: Manufacturing & Engineering | F9: Entry Level (0-2 yrs) | G9: Full-time | H9: On-site | I9: 1.75 | J9: 3 | K9: Design Engineering, Drawing, Structural Design, Technical Reports | L9: 45973
A10: J0107 | B10: Senior Cloud Engineer | C10: ZS | D10: Pune | E10: IT / Software | F10: Mid Level (3-6 yrs) | G10: Full-time | H10: On-site | I10: 18 | J10: 33 | K10: kubernetes, security compliance, microsoft azure, devops | L10: 45968
A11: J0160 | B11: Customer Service Executive | C11: Bangalore Watch Company | D11: Bangalore | E11: Customer Service & BPO | F11: Mid Level (3-6 yrs) | G11: Full-time | H11: On-site | I11: 3.6 | J11: 6 | K11: Customer Relationship, Customer Management, Customer Handling, Handling | L11: 45972
A12: J0339 | B12: Interior Designer | C12: Reflections Designs | D12: Mumbai Suburban | E12: Other / General Business | F12: Entry Level (0-2 yrs) | G12: Full-time | H12: On-site | I12: 26.4 | J12: 64.8 | L12: 45974
A13: J0161 | B13: Corporate Sales Manager | C13: Next Vision Business Solution | D13: Hyderabad | E13: BFSI (Banking/Finance/Insurance) | F13: Entry Level (0-2 yrs) | G13: Full-time | H13: On-site | I13: 4 | J13: 4.75 | K13: Sales, Agency Channel, Life Insurance, Broking | L13: 45976
A14: J0245 | B14: Education Counsellor | C14: PRO Hr Complete Solutions | D14: Kolkata | E14: Marketing & Advertising | F14: Entry Level (0-2 yrs) | G14: Full-time | H14: On-site | I14: 1.75 | J14: 2.5 | K14: Admission Counselling, Educational Sales, Lead Generation, Telesales | L14: 45974
A15: J0048 | B15: Senior Web / Full-Stack Developer | C15: Kiya.ai | D15: Chennai | E15: IT / Software | F15: Mid Level (3-6 yrs) | G15: Full-time | H15: Hybrid | I15: 15 | J15: 25 | K15: Frontend Development Skills, Full-Stack Integration, Performance tuning, CSS | L15: 45969
A16: J0003 | B16: AI Automation Professional | C16: Cognizant | D16: Chennai | E16: Other / General Business | F16: Senior Level (7+ yrs) | G16: Full-time | H16: On-site | K16: AI Automation, AI Services, project execution, Automation Gen AI | L16: 45976
A17: J0247 | B17: ASSOCIATE SOFTWARE ENGINEER | C17: Orcapod Consulting Services | D17: Pune | E17: IT / Software | F17: Mid Level (3-6 yrs) | G17: Full-time | H17: On-site | I17: 4 | J17: 9 | K17: MVVM, WPF, Desktop Application, c# | L17: 45976
A18: J0019 | B18: Node Js Developer | C18: V2soft | D18: Bengaluru | E18: IT / Software | F18: Mid Level (3-6 yrs) | G18: Full-time | H18: On-site | I18: 8 | J18: 18 | K18: Node.Js, Microservices, NoSQL, Docker | L18: 45972
A19: J0167 | B19: Uregently Required - Sales Executive | C19: Tekpillar | D19: Jamnagar | E19: IT / Software | F19: Entry Level (0-2 yrs) | G19: Full-time | H19: On-site | I19: 3.5 | J19: 4 | K19: Sales, Field Sales, Banking And Insurance, B2C Sales | L19: 45976
A20: J0081 | B20: Customer Care Executive | C20: Talent Corner Hr Services | D20: Ahmedabad | E20: Other / General Business | F20: Entry Level (0-2 yrs) | G20: Full-time | H20: On-site | I20: 1.5 | J20: 2.5 | K20: Handling Customer Queries, Complaint Handling, Complaint Management, Customer Complaints | L20: 45973
A21: J0234 | B21: Desktop/ Network Engineer (POS application) (Meerut- Agra) | C21: Team Computers | D21: Meerut | E21: IT / Software | F21: Mid Level (3-6 yrs) | G21: Full-time | H21: On-site | I21: 0.5 | J21: 2.75 | K21: Desktop Support, Network Support, OS Installation, Outlook Configuration | L21: 45966
A22: J0096 | B22: Technical/ Service Desk Engineer - chennai | C22: Nsquare It Solutions | D22: Chennai | E22: IT / Software | F22: Entry Level (0-2 yrs) | G22: Full-time | H22: On-site | I22: 1.5 | J22: 4 | K22: Desktop Administration, System Administration, fresher, Desktop Support | L22: 45968
A23: J0098 | B23: Solution Architect | C23: Nitor | D23: Pune | E23: IT / Software | F23: Senior Level (7+ yrs) | G23: Full-time | H23: Hybrid | I23: 18 | J23: 33 | K23: Solution Architecting, Java, Microservices, Architecting | L23: 45973
A24: J0299 | B24: HR compliance | C24: Executives Corridor | D24: Mumbai | E24: Education & Training | F24: Mid Level (3-6 yrs) | G24: Full-time | H24: On-site | K24: Payroll, statutory compliance, challan, Uan | L24: 45966
A25: J0233 | B25: URGENT HIRING MUSIC TEACHER (ANDHRA PRADESH) | C25: Mdn Edify Education | D25: Anantapur | E25: Education & Training | F25: Entry Level (0-2 yrs) | G25: Full-time | H25: On-site | I25: 1.75 | J25: 3.25 | K25: Singing, Music, Classical, Composing | L25: 45972
A26: J0089 | B26: Sales Manager - Indiamart || Gujarat | C26: IndiaMART | D26: Rajkot | E26: Sales & Business Development | F26: Mid Level (3-6 yrs) | G26: Full-time | H26: On-site | K26: Sales, Team Handling, Territory Sales, New Client Acquisition | L26: 45969
A27: J0432 | B27: Business Development Executive | C27: Wenger & Watson | D27: Pune | E27: HR & Staffing | F27: Entry Level (0-2 yrs) | G27: Full-time | H27: On-site | I27: 1.25 | J27: 3 | K27: Lead Generation, Business Development, B2B, New Client Acquisition | L27: 45968
A28: J0229 | B28: Digital Marketing Executive | C28: Verve Global Services | D28: Pune | E28: Marketing & Advertising | F28: Entry Level (0-2 yrs) | G28: Full-time | H28: On-site | I28: 2.4 | J28: 3 | K28: Content Marketing, Social Media Marketing, SEO, Marketing | L28: 45973
A29: J0403 | B29: Zonal Head Sales | C29: Workex | D29: Ahmedabad | E29: Sales & Business Development | F29: Mid Level (3-6 yrs) | G29: Full-time | H29: On-site | I29: 5 | J29: 10 | K29: Dealer Sales, Distributor Sales, Channel Sales, HVAC | L29: 45967
A30: J0387 | B30: Quality & MR -CNC & VMC Production line , Pune Chakan | C30: HR Innovation Group | D30: Pune | E30: Manufacturing & Engineering | F30: Senior Level (7+ yrs) | G30: Full-time | H30: On-site | I30: 5 | J30: 6 | K30: ISO, IATF, QMS, Quality System Management | L30: 45973
A31: J0221 | B31: Operations Executive | C31: Indian Institute of Emergency Medical Services(IIEMS) | D31: Kottayam | E31: Customer Service & BPO | F31: Entry Level (0-2 yrs) | G31: Full-time | H31: On-site | K31: back office, back office operations, customer service, pivot table | L31: 45968
A32: J0395 | B32: Civil Site Engineer | C32: Workart Hr Solutions | D32: Palitana | E32: Manufacturing & Engineering | F32: Mid Level (3-6 yrs) | G32: Full-time | H32: On-site | I32: 3 | J32: 7 | K32: Site Engineering, Site Planning, Site Management, Site Supervision | L32: 45969
A33: J0100 | B33: Urgent Hiring - Relationship Manager | C33: Supro Consulting | D33: Haldwani | E33: IT / Software | F33: Entry Level (0-2 yrs) | G33: Full-time | H33: On-site | I33: 3 | J33: 3.75 | K33: Sales, Team Handling, Credit Card Sales, Telesales | L33: 45970
A34: J0365 | B34: Accounts Officer | C34: DMart | D34: Rajpura | E34: BFSI (Banking/Finance/Insurance) | F34: Mid Level (3-6 yrs) | G34: Full-time | H34: On-site | I34: 3 | J34: 4.75 | K34: MIS, Daily Expense, Bank Reconciliation, Accounting | L34: 45976
A35: J0423 | B35: Technical/ Service Desk Engineer - chennai | C35: Nsquare It Solutions | D35: Chennai | E35: IT / Software | F35: Entry Level (0-2 yrs) | G35: Full-time | H35: On-site | I35: 1.5 | J35: 4 | K35: Desktop Administration, System Administration, fresher, Desktop Support | L35: 45968
A36: J0340 | B36: Placement Coordinator | C36: The World Of Automation | D36: Pune | E36: Sales & Business Development | F36: Entry Level (0-2 yrs) | G36: Full-time | H36: On-site | I36: 1.8 | J36: 3.6 | K36: Placement Coordination, Business Tie Ups, Corporate Relations, Skill Development | L36: 45970
A37: J0195 | B37: Logistics In charge - Fly Ash | C37: Refex Industries | D37: Ramagundam | E37: Logistics & Supply Chain | F37: Mid Level (3-6 yrs) | G37: Full-time | H37: On-site | I37: 4 | J37: 7 | K37: Fleet Management, Logistics Operations, Logistics, Management | L37: 45973
A38: J0376 | B38: WFH, French Voice process, sal up To 5.4 lpa | C38: Creative Hands HR | D38: Remote | E38: Customer Service & BPO | F38: Entry Level (0-2 yrs) | G38: Full-time | H38: Remote | I38: 3.5 | J38: 5.5 | K38: Marathi, Assamese, Bengali, voice process | L38: 45968
A39: J0346 | B39: SQL Developer | C39: F&F Consulting Services | D39: Panchkula | E39: IT / Software | F39: Mid Level (3-6 yrs) | G39: Full-time | H39: On-site | I39: 6 | J39: 7 | K39: SQL Development, optimizing database, complex SQL queries, SQL queries | L39: 45967
A40: J0128 | B40: SR FrontEnd Developer (Angular) | C40: Seven N Consulting | D40: Pune | E40: IT / Software | F40: Mid Level (3-6 yrs) | G40: Full-time | H40: On-site | K40: IT services, CSS, Web technologies, Front end | L40: 45973
...

Sheet Cleaned_Data
A1: Data Cleaning Steps Applied (see Raw_Data → Cleaned_Data)
A2: 1. Removed extra spaces from text fields using TRIM.
A3: 2. Standardized text casing (e.g. job titles) using PROPER.
A4: 3. Standardized location spellings (Bangalore→Bengaluru, Gurgaon→Gurugram, New Delhi→Delhi) using IF.
A5: 4. Filled missing Experience_Level and Required_Skills with "Not Specified" using IF, instead of leaving blank cells.
A6: 5. Checked Salary_Min/Salary_Max are numeric; postings with "Not Disclosed" salary are left blank (excluded automatically from salary averages).
A7: 6. Flagged duplicate postings (same title, company, location and date) using a COUNTIFS-based Duplicate_Flag column; duplicates are excluded from the Analysis sheet.
A8: 7. Added calculated columns: Average_Salary, Salary_Range, Posting_Month, and Job_Role_Category (grouping similar job titles using SEARCH + IFS).
A10: Job_ID | B10: Job_Title | C10: Company | D10: Location | E10: Industry | F10: Experience_Level | G10: Employment_Type | H10: Work_Mode | I10: Salary_Min | J10: Salary_Max | K10: Required_Skills | L10: Posting_Date | M10: Average_Salary | N10: Salary_Range | O10: Posting_Month | P10: Job_Role_Category | Q10: Duplicate_Flag
A11: =Raw_Data!A2 | B11: =PROPER(TRIM(Raw_Data!B2)) | C11: =TRIM(Raw_Data!C2) | D11: =IF(PROPER(TRIM(Raw_Data!D2))="Bangalore","Bengaluru",IF(PROPER(TRIM(Raw_Data!D2))="Gurgaon","Gurugram",IF(OR(PROPER(TRIM(Raw_Data!D2))="New Delhi",PROPER(TRIM(Raw_Data!D2))="Delhi"),"Delhi",PROPER(TRIM(Raw_Data!D2))))) | E11: =Raw_Data!E2 | F11: =IF(TRIM(Raw_Data!F2&"")="","Not Specified",Raw_Data!F2) | G11: =Raw_Data!G2 | H11: =Raw_Data!H2 | I11: =IF(Raw_Data!I2="","",Raw_Data!I2) | J11: =IF(Raw_Data!J2="","",Raw_Data!J2) | K11: =IF(TRIM(Raw_Data!K2&"")="","Not Specified",Raw_Data!K2) | L11: =Raw_Data!L2 | M11: =IF(OR(I11="",J11=""),"",(I11+J11)/2) | N11: =IF(OR(I11="",J11=""),"",J11-I11) | O11: =TEXT(L11,"mmm-yyyy") | P11: =_xlfn.IFS(ISNUMBER(SEARCH("data analy",B11)),"Data Analyst",ISNUMBER(SEARCH("business analy",B11)),"Business Analyst",OR(ISNUMBER(SEARCH("developer",B11)),ISNUMBER(SEARCH("software engineer",B11)),ISNUMBER(SEARCH("programmer",B11))),"Software Developer",ISNUMBER(SEARCH("business development",B11)),"Business Development",ISNUMBER(SEARCH("sales",B11)),"Sales Executive",ISNUMBER(SEARCH("marketing",B11)),"Marketing Executive",OR(ISNUMBER(SEARCH("hr ",B11)),ISNUMBER(SEARCH("recruit",B11)),ISNUMBER(SEARCH("human resource",B11))),"HR / Recruiter",OR(ISNUMBER(SEARCH("account",B11)),ISNUMBER(SEARCH("finance",B11)),ISNUMBER(SEARCH("tax",B11)),ISNUMBER(SEARCH("audit",B11))),"Accountant / Finance",OR(ISNUMBER(SEARCH("customer service",B11)),ISNUMBER(SEARCH("customer support",B11)),ISNUMBER(SEARCH("customer care",B11)),ISNUMBER(SEARCH("voice process",B11)),ISNUMBER(SEARCH("bpo",B11))),"Customer Support",ISNUMBER(SEARCH("engineer",B11)),"Engineer (Technical)",ISNUMBER(SEARCH("manager",B11)),"Manager",OR(ISNUMBER(SEARCH("teacher",B11)),ISNUMBER(SEARCH("trainer",B11)),ISNUMBER(SEARCH("faculty",B11))),"Teacher / Trainer",OR(ISNUMBER(SEARCH("doctor",B11)),ISNUMBER(SEARCH("nurse",B11)),ISNUMBER(SEARCH("medical",B11)),ISNUMBER(SEARCH("pharma",B11)),ISNUMBER(SEARCH("clinical",B11))),"Healthcare",TRUE,"Other") | Q11: =IF(COUNTIFS($B$11:B11,B11,$C$11:C11,C11,$D$11:D11,D11,$L$11:L11,L11)>1,"Duplicate","Unique")
A12: =Raw_Data!A3 | B12: =PROPER(TRIM(Raw_Data!B3)) | C12: =TRIM(Raw_Data!C3) | D12: =IF(PROPER(TRIM(Raw_Data!D3))="Bangalore","Bengaluru",IF(PROPER(TRIM(Raw_Data!D3))="Gurgaon","Gurugram",IF(OR(PROPER(TRIM(Raw_Data!D3))="New Delhi",PROPER(TRIM(Raw_Data!D3))="Delhi"),"Delhi",PROPER(TRIM(Raw_Data!D3))))) | E12: =Raw_Data!E3 | F12: =IF(TRIM(Raw_Data!F3&"")="","Not Specified",Raw_Data!F3) | G12: =Raw_Data!G3 | H12: =Raw_Data!H3 | I12: =IF(Raw_Data!I3="","",Raw_Data!I3) | J12: =IF(Raw_Data!J3="","",Raw_Data!J3) | K12: =IF(TRIM(Raw_Data!K3&"")="","Not Specified",Raw_Data!K3) | L12: =Raw_Data!L3 | M12: =IF(OR(I12="",J12=""),"",(I12+J12)/2) | N12: =IF(OR(I12="",J12=""),"",J12-I12) | O12: =TEXT(L12,"mmm-yyyy") | P12: =_xlfn.IFS(ISNUMBER(SEARCH("data analy",B12)),"Data Analyst",ISNUMBER(SEARCH("business analy",B12)),"Business Analyst",OR(ISNUMBER(SEARCH("developer",B12)),ISNUMBER(SEARCH("software engineer",B12)),ISNUMBER(SEARCH("programmer",B12))),"Software Developer",ISNUMBER(SEARCH("business development",B12)),"Business Development",ISNUMBER(SEARCH("sales",B12)),"Sales Executive",ISNUMBER(SEARCH("marketing",B12)),"Marketing Executive",OR(ISNUMBER(SEARCH("hr ",B12)),ISNUMBER(SEARCH("recruit",B12)),ISNUMBER(SEARCH("human resource",B12))),"HR / Recruiter",OR(ISNUMBER(SEARCH("account",B12)),ISNUMBER(SEARCH("finance",B12)),ISNUMBER(SEARCH("tax",B12)),ISNUMBER(SEARCH("audit",B12))),"Accountant / Finance",OR(ISNUMBER(SEARCH("customer service",B12)),ISNUMBER(SEARCH("customer support",B12)),ISNUMBER(SEARCH("customer care",B12)),ISNUMBER(SEARCH("voice process",B12)),ISNUMBER(SEARCH("bpo",B12))),"Customer Support",ISNUMBER(SEARCH("engineer",B12)),"Engineer (Technical)",ISNUMBER(SEARCH("manager",B12)),"Manager",OR(ISNUMBER(SEARCH("teacher",B12)),ISNUMBER(SEARCH("trainer",B12)),ISNUMBER(SEARCH("faculty",B12))),"Teacher / Trainer",OR(ISNUMBER(SEARCH("doctor",B12)),ISNUMBER(SEARCH("nurse",B12)),ISNUMBER(SEARCH("medical",B12)),ISNUMBER(SEARCH("pharma",B12)),ISNUMBER(SEARCH("clinical",B12))),"Healthcare",TRUE,"Other") | Q12: =IF(COUNTIFS($B$11:B12,B12,$C$11:C12,C12,$D$11:D12,D12,$L$11:L12,L12)>1,"Duplicate","Unique")
A13: =Raw_Data!A4 | B13: =PROPER(TRIM(Raw_Data!B4)) | C13: =TRIM(Raw_Data!C4) | D13: =IF(PROPER(TRIM(Raw_Data!D4))="Bangalore","Bengaluru",IF(PROPER(TRIM(Raw_Data!D4))="Gurgaon","Gurugram",IF(OR(PROPER(TRIM(Raw_Data!D4))="New Delhi",PROPER(TRIM(Raw_Data!D4))="Delhi"),"Delhi",PROPER(TRIM(Raw_Data!D4))))) | E13: =Raw_Data!E4 | F13: =IF(TRIM(Raw_Data!F4&"")="","Not Specified",Raw_Data!F4) | G13: =Raw_Data!G4 | H13: =Raw_Data!H4 | I13: =IF(Raw_Data!I4="","",Raw_Data!I4) | J13: =IF(Raw_Data!J4="","",Raw_Data!J4) | K13: =IF(TRIM(Raw_Data!K4&"")="","Not Specified",Raw_Data!K4) | L13: =Raw_Data!L4 | M13: =IF(OR(I13="",J13=""),"",(I13+J13)/2) | N13: =IF(OR(I13="",J13=""),"",J13-I13) | O13: =TEXT(L13,"mmm-yyyy") | P13: =_xlfn.IFS(ISNUMBER(SEARCH("data analy",B13)),"Data Analyst",ISNUMBER(SEARCH("business analy",B13)),"Business Analyst",OR(ISNUMBER(SEARCH("developer",B13)),ISNUMBER(SEARCH("software engineer",B13)),ISNUMBER(SEARCH("programmer",B13))),"Software Developer",ISNUMBER(SEARCH("business development",B13)),"Business Development",ISNUMBER(SEARCH("sales",B13)),"Sales Executive",ISNUMBER(SEARCH("marketing",B13)),"Marketing Executive",OR(ISNUMBER(SEARCH("hr ",B13)),ISNUMBER(SEARCH("recruit",B13)),ISNUMBER(SEARCH("human resource",B13))),"HR / Recruiter",OR(ISNUMBER(SEARCH("account",B13)),ISNUMBER(SEARCH("finance",B13)),ISNUMBER(SEARCH("tax",B13)),ISNUMBER(SEARCH("audit",B13))),"Accountant / Finance",OR(ISNUMBER(SEARCH("customer service",B13)),ISNUMBER(SEARCH("customer support",B13)),ISNUMBER(SEARCH("customer care",B13)),ISNUMBER(SEARCH("voice process",B13)),ISNUMBER(SEARCH("bpo",B13))),"Customer Support",ISNUMBER(SEARCH("engineer",B13)),"Engineer (Technical)",ISNUMBER(SEARCH("manager",B13)),"Manager",OR(ISNUMBER(SEARCH("teacher",B13)),ISNUMBER(SEARCH("trainer",B13)),ISNUMBER(SEARCH("faculty",B13))),"Teacher / Trainer",OR(ISNUMBER(SEARCH("doctor",B13)),ISNUMBER(SEARCH("nurse",B13)),ISNUMBER(SEARCH("medical",B13)),ISNUMBER(SEARCH("pharma",B13)),ISNUMBER(SEARCH("clinical",B13))),"Healthcare",TRUE,"Other") | Q13: =IF(COUNTIFS($B$11:B13,B13,$C$11:C13,C13,$D$11:D13,D13,$L$11:L13,L13)>1,"Duplicate","Unique")
A14: =Raw_Data!A5 | B14: =PROPER(TRIM(Raw_Data!B5)) | C14: =TRIM(Raw_Data!C5) | D14: =IF(PROPER(TRIM(Raw_Data!D5))="Bangalore","Bengaluru",IF(PROPER(TRIM(Raw_Data!D5))="Gurgaon","Gurugram",IF(OR(PROPER(TRIM(Raw_Data!D5))="New Delhi",PROPER(TRIM(Raw_Data!D5))="Delhi"),"Delhi",PROPER(TRIM(Raw_Data!D5))))) | E14: =Raw_Data!E5 | F14: =IF(TRIM(Raw_Data!F5&"")="","Not Specified",Raw_Data!F5) | G14: =Raw_Data!G5 | H14: =Raw_Data!H5 | I14: =IF(Raw_Data!I5="","",Raw_Data!I5) | J14: =IF(Raw_Data!J5="","",Raw_Data!J5) | K14: =IF(TRIM(Raw_Data!K5&"")="","Not Specified",Raw_Data!K5) | L14: =Raw_Data!L5 | M14: =IF(OR(I14="",J14=""),"",(I14+J14)/2) | N14: =IF(OR(I14="",J14=""),"",J14-I14) | O14: =TEXT(L14,"mmm-yyyy") | P14: =_xlfn.IFS(ISNUMBER(SEARCH("data analy",B14)),"Data Analyst",ISNUMBER(SEARCH("business analy",B14)),"Business Analyst",OR(ISNUMBER(SEARCH("developer",B14)),ISNUMBER(SEARCH("software engineer",B14)),ISNUMBER(SEARCH("programmer",B14))),"Software Developer",ISNUMBER(SEARCH("business development",B14)),"Business Development",ISNUMBER(SEARCH("sales",B14)),"Sales Executive",ISNUMBER(SEARCH("marketing",B14)),"Marketing Executive",OR(ISNUMBER(SEARCH("hr ",B14)),ISNUMBER(SEARCH("recruit",B14)),ISNUMBER(SEARCH("human resource",B14))),"HR / Recruiter",OR(ISNUMBER(SEARCH("account",B14)),ISNUMBER(SEARCH("finance",B14)),ISNUMBER(SEARCH("tax",B14)),ISNUMBER(SEARCH("audit",B14))),"Accountant / Finance",OR(ISNUMBER(SEARCH("customer service",B14)),ISNUMBER(SEARCH("customer support",B14)),ISNUMBER(SEARCH("customer care",B14)),ISNUMBER(SEARCH("voice process",B14)),ISNUMBER(SEARCH("bpo",B14))),"Customer Support",ISNUMBER(SEARCH("engineer",B14)),"Engineer (Technical)",ISNUMBER(SEARCH("manager",B14)),"Manager",OR(ISNUMBER(SEARCH("teacher",B14)),ISNUMBER(SEARCH("trainer",B14)),ISNUMBER(SEARCH("faculty",B14))),"Teacher / Trainer",OR(ISNUMBER(SEARCH("doctor",B14)),ISNUMBER(SEARCH("nurse",B14)),ISNUMBER(SEARCH("medical",B14)),ISNUMBER(SEARCH("pharma",B14)),ISNUMBER(SEARCH("clinical",B14))),"Healthcare",TRUE,"Other") | Q14: =IF(COUNTIFS($B$11:B14,B14,$C$11:C14,C14,$D$11:D14,D14,$L$11:L14,L14)>1,"Duplicate","Unique")
A15: =Raw_Data!A6 | B15: =PROPER(TRIM(Raw_Data!B6)) | C15: =TRIM(Raw_Data!C6) | D15: =IF(PROPER(TRIM(Raw_Data!D6))="Bangalore","Bengaluru",IF(PROPER(TRIM(Raw_Data!D6))="Gurgaon","Gurugram",IF(OR(PROPER(TRIM(Raw_Data!D6))="New Delhi",PROPER(TRIM(Raw_Data!D6))="Delhi"),"Delhi",PROPER(TRIM(Raw_Data!D6))))) | E15: =Raw_Data!E6 | F15: =IF(TRIM(Raw_Data!F6&"")="","Not Specified",Raw_Data!F6) | G15: =Raw_Data!G6 | H15: =Raw_Data!H6 | I15: =IF(Raw_Data!I6="","",Raw_Data!I6) | J15: =IF(Raw_Data!J6="","",Raw_Data!J6) | K15: =IF(TRIM(Raw_Data!K6&"")="","Not Specified",Raw_Data!K6) | L15: =Raw_Data!L6 | M15: =IF(OR(I15="",J15=""),"",(I15+J15)/2) | N15: =IF(OR(I15="",J15=""),"",J15-I15) | O15: =TEXT(L15,"mmm-yyyy") | P15: =_xlfn.IFS(ISNUMBER(SEARCH("data analy",B15)),"Data Analyst",ISNUMBER(SEARCH("business analy",B15)),"Business Analyst",OR(ISNUMBER(SEARCH("developer",B15)),ISNUMBER(SEARCH("software engineer",B15)),ISNUMBER(SEARCH("programmer",B15))),"Software Developer",ISNUMBER(SEARCH("business development",B15)),"Business Development",ISNUMBER(SEARCH("sales",B15)),"Sales Executive",ISNUMBER(SEARCH("marketing",B15)),"Marketing Executive",OR(ISNUMBER(SEARCH("hr ",B15)),ISNUMBER(SEARCH("recruit",B15)),ISNUMBER(SEARCH("human resource",B15))),"HR / Recruiter",OR(ISNUMBER(SEARCH("account",B15)),ISNUMBER(SEARCH("finance",B15)),ISNUMBER(SEARCH("tax",B15)),ISNUMBER(SEARCH("audit",B15))),"Accountant / Finance",OR(ISNUMBER(SEARCH("customer service",B15)),ISNUMBER(SEARCH("customer support",B15)),ISNUMBER(SEARCH("customer care",B15)),ISNUMBER(SEARCH("voice process",B15)),ISNUMBER(SEARCH("bpo",B15))),"Customer Support",ISNUMBER(SEARCH("engineer",B15)),"Engineer (Technical)",ISNUMBER(SEARCH("manager",B15)),"Manager",OR(ISNUMBER(SEARCH("teacher",B15)),ISNUMBER(SEARCH("trainer",B15)),ISNUMBER(SEARCH("faculty",B15))),"Teacher / Trainer",OR(ISNUMBER(SEARCH("doctor",B15)),ISNUMBER(SEARCH("nurse",B15)),ISNUMBER(SEARCH("medical",B15)),ISNUMBER(SEARCH("pharma",B15)),ISNUMBER(SEARCH("clinical",B15))),"Healthcare",TRUE,"Other") | Q15: =IF(COUNTIFS($B$11:B15,B15,$C$11:C15,C15,$D$11:D15,D15,$L$11:L15,L15)>1,"Duplicate","Unique")
A16: =Raw_Data!A7 | B16: =PROPER(TRIM(Raw_Data!B7)) | C16: =TRIM(Raw_Data!C7) | D16: =IF(PROPER(TRIM(Raw_Data!D7))="Bangalore","Bengaluru",IF(PROPER(TRIM(Raw_Data!D7))="Gurgaon","Gurugram",IF(OR(PROPER(TRIM(Raw_Data!D7))="New Delhi",PROPER(TRIM(Raw_Data!D7))="Delhi"),"Delhi",PROPER(TRIM(Raw_Data!D7))))) | E16: =Raw_Data!E7 | F16: =IF(TRIM(Raw_Data!F7&"")="","Not Specified",Raw_Data!F7) | G16: =Raw_Data!G7 | H16: =Raw_Data!H7 | I16: =IF(Raw_Data!I7="","",Raw_Data!I7) | J16: =IF(Raw_Data!J7="","",Raw_Data!J7) | K16: =IF(TRIM(Raw_Data!K7&"")="","Not Specified",Raw_Data!K7) | L16: =Raw_Data!L7 | M16: =IF(OR(I16="",J16=""),"",(I16+J16)/2) | N16: =IF(OR(I16="",J16=""),"",J16-I16) | O16: =TEXT(L16,"mmm-yyyy") | P16: =_xlfn.IFS(ISNUMBER(SEARCH("data analy",B16)),"Data Analyst",ISNUMBER(SEARCH("business analy",B16)),"Business Analyst",OR(ISNUMBER(SEARCH("developer",B16)),ISNUMBER(SEARCH("software engineer",B16)),ISNUMBER(SEARCH("programmer",B16))),"Software Developer",ISNUMBER(SEARCH("business development",B16)),"Business Development",ISNUMBER(SEARCH("sales",B16)),"Sales Executive",ISNUMBER(SEARCH("marketing",B16)),"Marketing Executive",OR(ISNUMBER(SEARCH("hr ",B16)),ISNUMBER(SEARCH("recruit",B16)),ISNUMBER(SEARCH("human resource",B16))),"HR / Recruiter",OR(ISNUMBER(SEARCH("account",B16)),ISNUMBER(SEARCH("finance",B16)),ISNUMBER(SEARCH("tax",B16)),ISNUMBER(SEARCH("audit",B16))),"Accountant / Finance",OR(ISNUMBER(SEARCH("customer service",B16)),ISNUMBER(SEARCH("customer support",B16)),ISNUMBER(SEARCH("customer care",B16)),ISNUMBER(SEARCH("voice process",B16)),ISNUMBER(SEARCH("bpo",B16))),"Customer Support",ISNUMBER(SEARCH("engineer",B16)),"Engineer (Technical)",ISNUMBER(SEARCH("manager",B16)),"Manager",OR(ISNUMBER(SEARCH("teacher",B16)),ISNUMBER(SEARCH("trainer",B16)),ISNUMBER(SEARCH("faculty",B16))),"Teacher / Trainer",OR(ISNUMBER(SEARCH("doctor",B16)),ISNUMBER(SEARCH("nurse",B16)),ISNUMBER(SEARCH("medical",B16)),ISNUMBER(SEARCH("pharma",B16)),ISNUMBER(SEARCH("clinical",B16))),"Healthcare",TRUE,"Other") | Q16: =IF(COUNTIFS($B$11:B16,B16,$C$11:C16,C16,$D$11:D16,D16,$L$11:L16,L16)>1,"Duplicate","Unique")
A17: =Raw_Data!A8 | B17: =PROPER(TRIM(Raw_Data!B8)) | C17: =TRIM(Raw_Data!C8) | D17: =IF(PROPER(TRIM(Raw_Data!D8))="Bangalore","Bengaluru",IF(PROPER(TRIM(Raw_Data!D8))="Gurgaon","Gurugram",IF(OR(PROPER(TRIM(Raw_Data!D8))="New Delhi",PROPER(TRIM(Raw_Data!D8))="Delhi"),"Delhi",PROPER(TRIM(Raw_Data!D8))))) | E17: =Raw_Data!E8 | F17: =IF(TRIM(Raw_Data!F8&"")="","Not Specified",Raw_Data!F8) | G17: =Raw_Data!G8 | H17: =Raw_Data!H8 | I17: =IF(Raw_Data!I8="","",Raw_Data!I8) | J17: =IF(Raw_Data!J8="","",Raw_Data!J8) | K17: =IF(TRIM(Raw_Data!K8&"")="","Not Specified",Raw_Data!K8) | L17: =Raw_Data!L8 | M17: =IF(OR(I17="",J17=""),"",(I17+J17)/2) | N17: =IF(OR(I17="",J17=""),"",J17-I17) | O17: =TEXT(L17,"mmm-yyyy") | P17: =_xlfn.IFS(ISNUMBER(SEARCH("data analy",B17)),"Data Analyst",ISNUMBER(SEARCH("business analy",B17)),"Business Analyst",OR(ISNUMBER(SEARCH("developer",B17)),ISNUMBER(SEARCH("software engineer",B17)),ISNUMBER(SEARCH("programmer",B17))),"Software Developer",ISNUMBER(SEARCH("business development",B17)),"Business Development",ISNUMBER(SEARCH("sales",B17)),"Sales Executive",ISNUMBER(SEARCH("marketing",B17)),"Marketing Executive",OR(ISNUMBER(SEARCH("hr ",B17)),ISNUMBER(SEARCH("recruit",B17)),ISNUMBER(SEARCH("human resource",B17))),"HR / Recruiter",OR(ISNUMBER(SEARCH("account",B17)),ISNUMBER(SEARCH("finance",B17)),ISNUMBER(SEARCH("tax",B17)),ISNUMBER(SEARCH("audit",B17))),"Accountant / Finance",OR(ISNUMBER(SEARCH("customer service",B17)),ISNUMBER(SEARCH("customer support",B17)),ISNUMBER(SEARCH("customer care",B17)),ISNUMBER(SEARCH("voice process",B17)),ISNUMBER(SEARCH("bpo",B17))),"Customer Support",ISNUMBER(SEARCH("engineer",B17)),"Engineer (Technical)",ISNUMBER(SEARCH("manager",B17)),"Manager",OR(ISNUMBER(SEARCH("teacher",B17)),ISNUMBER(SEARCH("trainer",B17)),ISNUMBER(SEARCH("faculty",B17))),"Teacher / Trainer",OR(ISNUMBER(SEARCH("doctor",B17)),ISNUMBER(SEARCH("nurse",B17)),ISNUMBER(SEARCH("medical",B17)),ISNUMBER(SEARCH("pharma",B17)),ISNUMBER(SEARCH("clinical",B17))),"Healthcare",TRUE,"Other") | Q17: =IF(COUNTIFS($B$11:B17,B17,$C$11:C17,C17,$D$11:D17,D17,$L$11:L17,L17)>1,"Duplicate","Unique")
A18: =Raw_Data!A9 | B18: =PROPER(TRIM(Raw_Data!B9)) | C18: =TRIM(Raw_Data!C9) | D18: =IF(PROPER(TRIM(Raw_Data!D9))="Bangalore","Bengaluru",IF(PROPER(TRIM(Raw_Data!D9))="Gurgaon","Gurugram",IF(OR(PROPER(TRIM(Raw_Data!D9))="New Delhi",PROPER(TRIM(Raw_Data!D9))="Delhi"),"Delhi",PROPER(TRIM(Raw_Data!D9))))) | E18: =Raw_Data!E9 | F18: =IF(TRIM(Raw_Data!F9&"")="","Not Specified",Raw_Data!F9) | G18: =Raw_Data!G9 | H18: =Raw_Data!H9 | I18: =IF(Raw_Data!I9="","",Raw_Data!I9) | J18: =IF(Raw_Data!J9="","",Raw_Data!J9) | K18: =IF(TRIM(Raw_Data!K9&"")="","Not Specified",Raw_Data!K9) | L18: =Raw_Data!L9 | M18: =IF(OR(I18="",J18=""),"",(I18+J18)/2) | N18: =IF(OR(I18="",J18=""),"",J18-I18) | O18: =TEXT(L18,"mmm-yyyy") | P18: =_xlfn.IFS(ISNUMBER(SEARCH("data analy",B18)),"Data Analyst",ISNUMBER(SEARCH("business analy",B18)),"Business Analyst",OR(ISNUMBER(SEARCH("developer",B18)),ISNUMBER(SEARCH("software engineer",B18)),ISNUMBER(SEARCH("programmer",B18))),"Software Developer",ISNUMBER(SEARCH("business development",B18)),"Business Development",ISNUMBER(SEARCH("sales",B18)),"Sales Executive",ISNUMBER(SEARCH("marketing",B18)),"Marketing Executive",OR(ISNUMBER(SEARCH("hr ",B18)),ISNUMBER(SEARCH("recruit",B18)),ISNUMBER(SEARCH("human resource",B18))),"HR / Recruiter",OR(ISNUMBER(SEARCH("account",B18)),ISNUMBER(SEARCH("finance",B18)),ISNUMBER(SEARCH("tax",B18)),ISNUMBER(SEARCH("audit",B18))),"Accountant / Finance",OR(ISNUMBER(SEARCH("customer service",B18)),ISNUMBER(SEARCH("customer support",B18)),ISNUMBER(SEARCH("customer care",B18)),ISNUMBER(SEARCH("voice process",B18)),ISNUMBER(SEARCH("bpo",B18))),"Customer Support",ISNUMBER(SEARCH("engineer",B18)),"Engineer (Technical)",ISNUMBER(SEARCH("manager",B18)),"Manager",OR(ISNUMBER(SEARCH("teacher",B18)),ISNUMBER(SEARCH("trainer",B18)),ISNUMBER(SEARCH("faculty",B18))),"Teacher / Trainer",OR(ISNUMBER(SEARCH("doctor",B18)),ISNUMBER(SEARCH("nurse",B18)),ISNUMBER(SEARCH("medical",B18)),ISNUMBER(SEARCH("pharma",B18)),ISNUMBER(SEARCH("clinical",B18))),"Healthcare",TRUE,"Other") | Q18: =IF(COUNTIFS($B$11:B18,B18,$C$11:C18,C18,$D$11:D18,D18,$L$11:L18,L18)>1,"Duplicate","Unique")
A19: =Raw_Data!A10 | B19: =PROPER(TRIM(Raw_Data!B10)) | C19: =TRIM(Raw_Data!C10) | D19: =IF(PROPER(TRIM(Raw_Data!D10))="Bangalore","Bengaluru",IF(PROPER(TRIM(Raw_Data!D10))="Gurgaon","Gurugram",IF(OR(PROPER(TRIM(Raw_Data!D10))="New Delhi",PROPER(TRIM(Raw_Data!D10))="Delhi"),"Delhi",PROPER(TRIM(Raw_Data!D10))))) | E19: =Raw_Data!E10 | F19: =IF(TRIM(Raw_Data!F10&"")="","Not Specified",Raw_Data!F10) | G19: =Raw_Data!G10 | H19: =Raw_Data!H10 | I19: =IF(Raw_Data!I10="","",Raw_Data!I10) | J19: =IF(Raw_Data!J10="","",Raw_Data!J10) | K19: =IF(TRIM(Raw_Data!K10&"")="","Not Specified",Raw_Data!K10) | L19: =Raw_Data!L10 | M19: =IF(OR(I19="",J19=""),"",(I19+J19)/2) | N19: =IF(OR(I19="",J19=""),"",J19-I19) | O19: =TEXT(L19,"mmm-yyyy") | P19: =_xlfn.IFS(ISNUMBER(SEARCH("data analy",B19)),"Data Analyst",ISNUMBER(SEARCH("business analy",B19)),"Business Analyst",OR(ISNUMBER(SEARCH("developer",B19)),ISNUMBER(SEARCH("software engineer",B19)),ISNUMBER(SEARCH("programmer",B19))),"Software Developer",ISNUMBER(SEARCH("business development",B19)),"Business Development",ISNUMBER(SEARCH("sales",B19)),"Sales Executive",ISNUMBER(SEARCH("marketing",B19)),"Marketing Executive",OR(ISNUMBER(SEARCH("hr ",B19)),ISNUMBER(SEARCH("recruit",B19)),ISNUMBER(SEARCH("human resource",B19))),"HR / Recruiter",OR(ISNUMBER(SEARCH("account",B19)),ISNUMBER(SEARCH("finance",B19)),ISNUMBER(SEARCH("tax",B19)),ISNUMBER(SEARCH("audit",B19))),"Accountant / Finance",OR(ISNUMBER(SEARCH("customer service",B19)),ISNUMBER(SEARCH("customer support",B19)),ISNUMBER(SEARCH("customer care",B19)),ISNUMBER(SEARCH("voice process",B19)),ISNUMBER(SEARCH("bpo",B19))),"Customer Support",ISNUMBER(SEARCH("engineer",B19)),"Engineer (Technical)",ISNUMBER(SEARCH("manager",B19)),"Manager",OR(ISNUMBER(SEARCH("teacher",B19)),ISNUMBER(SEARCH("trainer",B19)),ISNUMBER(SEARCH("faculty",B19))),"Teacher / Trainer",OR(ISNUMBER(SEARCH("doctor",B19)),ISNUMBER(SEARCH("nurse",B19)),ISNUMBER(SEARCH("medical",B19)),ISNUMBER(SEARCH("pharma",B19)),ISNUMBER(SEARCH("clinical",B19))),"Healthcare",TRUE,"Other") | Q19: =IF(COUNTIFS($B$11:B19,B19,$C$11:C19,C19,$D$11:D19,D19,$L$11:L19,L19)>1,"Duplicate","Unique")
A20: =Raw_Data!A11 | B20: =PROPER(TRIM(Raw_Data!B11)) | C20: =TRIM(Raw_Data!C11) | D20: =IF(PROPER(TRIM(Raw_Data!D11))="Bangalore","Bengaluru",IF(PROPER(TRIM(Raw_Data!D11))="Gurgaon","Gurugram",IF(OR(PROPER(TRIM(Raw_Data!D11))="New Delhi",PROPER(TRIM(Raw_Data!D11))="Delhi"),"Delhi",PROPER(TRIM(Raw_Data!D11))))) | E20: =Raw_Data!E11 | F20: =IF(TRIM(Raw_Data!F11&"")="","Not Specified",Raw_Data!F11) | G20: =Raw_Data!G11 | H20: =Raw_Data!H11 | I20: =IF(Raw_Data!I11="","",Raw_Data!I11) | J20: =IF(Raw_Data!J11="","",Raw_Data!J11) | K20: =IF(TRIM(Raw_Data!K11&"")="","Not Specified",Raw_Data!K11) | L20: =Raw_Data!L11 | M20: =IF(OR(I20="",J20=""),"",(I20+J20)/2) | N20: =IF(OR(I20="",J20=""),"",J20-I20) | O20: =TEXT(L20,"mmm-yyyy") | P20: =_xlfn.IFS(ISNUMBER(SEARCH("data analy",B20)),"Data Analyst",ISNUMBER(SEARCH("business analy",B20)),"Business Analyst",OR(ISNUMBER(SEARCH("developer",B20)),ISNUMBER(SEARCH("software engineer",B20)),ISNUMBER(SEARCH("programmer",B20))),"Software Developer",ISNUMBER(SEARCH("business development",B20)),"Business Development",ISNUMBER(SEARCH("sales",B20)),"Sales Executive",ISNUMBER(SEARCH("marketing",B20)),"Marketing Executive",OR(ISNUMBER(SEARCH("hr ",B20)),ISNUMBER(SEARCH("recruit",B20)),ISNUMBER(SEARCH("human resource",B20))),"HR / Recruiter",OR(ISNUMBER(SEARCH("account",B20)),ISNUMBER(SEARCH("finance",B20)),ISNUMBER(SEARCH("tax",B20)),ISNUMBER(SEARCH("audit",B20))),"Accountant / Finance",OR(ISNUMBER(SEARCH("customer service",B20)),ISNUMBER(SEARCH("customer support",B20)),ISNUMBER(SEARCH("customer care",B20)),ISNUMBER(SEARCH("voice process",B20)),ISNUMBER(SEARCH("bpo",B20))),"Customer Support",ISNUMBER(SEARCH("engineer",B20)),"Engineer (Technical)",ISNUMBER(SEARCH("manager",B20)),"Manager",OR(ISNUMBER(SEARCH("teacher",B20)),ISNUMBER(SEARCH("trainer",B20)),ISNUMBER(SEARCH("faculty",B20))),"Teacher / Trainer",OR(ISNUMBER(SEARCH("doctor",B20)),ISNUMBER(SEARCH("nurse",B20)),ISNUMBER(SEARCH("medical",B20)),ISNUMBER(SEARCH("pharma",B20)),ISNUMBER(SEARCH("clinical",B20))),"Healthcare",TRUE,"Other") | Q20: =IF(COUNTIFS($B$11:B20,B20,$C$11:C20,C20,$D$11:D20,D20,$L$11:L20,L20)>1,"Duplicate","Unique")
A21: =Raw_Data!A12 | B21: =PROPER(TRIM(Raw_Data!B12)) | C21: =TRIM(Raw_Data!C12) | D21: =IF(PROPER(TRIM(Raw_Data!D12))="Bangalore","Bengaluru",IF(PROPER(TRIM(Raw_Data!D12))="Gurgaon","Gurugram",IF(OR(PROPER(TRIM(Raw_Data!D12))="New Delhi",PROPER(TRIM(Raw_Data!D12))="Delhi"),"Delhi",PROPER(TRIM(Raw_Data!D12))))) | E21: =Raw_Data!E12 | F21: =IF(TRIM(Raw_Data!F12&"")="","Not Specified",Raw_Data!F12) | G21: =Raw_Data!G12 | H21: =Raw_Data!H12 | I21: =IF(Raw_Data!I12="","",Raw_Data!I12) | J21: =IF(Raw_Data!J12="","",Raw_Data!J12) | K21: =IF(TRIM(Raw_Data!K12&"")="","Not Specified",Raw_Data!K12) | L21: =Raw_Data!L12 | M21: =IF(OR(I21="",J21=""),"",(I21+J21)/2) | N21: =IF(OR(I21="",J21=""),"",J21-I21) | O21: =TEXT(L21,"mmm-yyyy") | P21: =_xlfn.IFS(ISNUMBER(SEARCH("data analy",B21)),"Data Analyst",ISNUMBER(SEARCH("business analy",B21)),"Business Analyst",OR(ISNUMBER(SEARCH("developer",B21)),ISNUMBER(SEARCH("software engineer",B21)),ISNUMBER(SEARCH("programmer",B21))),"Software Developer",ISNUMBER(SEARCH("business development",B21)),"Business Development",ISNUMBER(SEARCH("sales",B21)),"Sales Executive",ISNUMBER(SEARCH("marketing",B21)),"Marketing Executive",OR(ISNUMBER(SEARCH("hr ",B21)),ISNUMBER(SEARCH("recruit",B21)),ISNUMBER(SEARCH("human resource",B21))),"HR / Recruiter",OR(ISNUMBER(SEARCH("account",B21)),ISNUMBER(SEARCH("finance",B21)),ISNUMBER(SEARCH("tax",B21)),ISNUMBER(SEARCH("audit",B21))),"Accountant / Finance",OR(ISNUMBER(SEARCH("customer service",B21)),ISNUMBER(SEARCH("customer support",B21)),ISNUMBER(SEARCH("customer care",B21)),ISNUMBER(SEARCH("voice process",B21)),ISNUMBER(SEARCH("bpo",B21))),"Customer Support",ISNUMBER(SEARCH("engineer",B21)),"Engineer (Technical)",ISNUMBER(SEARCH("manager",B21)),"Manager",OR(ISNUMBER(SEARCH("teacher",B21)),ISNUMBER(SEARCH("trainer",B21)),ISNUMBER(SEARCH("faculty",B21))),"Teacher / Trainer",OR(ISNUMBER(SEARCH("doctor",B21)),ISNUMBER(SEARCH("nurse",B21)),ISNUMBER(SEARCH("medical",B21)),ISNUMBER(SEARCH("pharma",B21)),ISNUMBER(SEARCH("clinical",B21))),"Healthcare",TRUE,"Other") | Q21: =IF(COUNTIFS($B$11:B21,B21,$C$11:C21,C21,$D$11:D21,D21,$L$11:L21,L21)>1,"Duplicate","Unique")
A22: =Raw_Data!A13 | B22: =PROPER(TRIM(Raw_Data!B13)) | C22: =TRIM(Raw_Data!C13) | D22: =IF(PROPER(TRIM(Raw_Data!D13))="Bangalore","Bengaluru",IF(PROPER(TRIM(Raw_Data!D13))="Gurgaon","Gurugram",IF(OR(PROPER(TRIM(Raw_Data!D13))="New Delhi",PROPER(TRIM(Raw_Data!D13))="Delhi"),"Delhi",PROPER(TRIM(Raw_Data!D13))))) | E22: =Raw_Data!E13 | F22: =IF(TRIM(Raw_Data!F13&"")="","Not Specified",Raw_Data!F13) | G22: =Raw_Data!G13 | H22: =Raw_Data!H13 | I22: =IF(Raw_Data!I13="","",Raw_Data!I13) | J22: =IF(Raw_Data!J13="","",Raw_Data!J13) | K22: =IF(TRIM(Raw_Data!K13&"")="","Not Specified",Raw_Data!K13) | L22: =Raw_Data!L13 | M22: =IF(OR(I22="",J22=""),"",(I22+J22)/2) | N22: =IF(OR(I22="",J22=""),"",J22-I22) | O22: =TEXT(L22,"mmm-yyyy") | P22: =_xlfn.IFS(ISNUMBER(SEARCH("data analy",B22)),"Data Analyst",ISNUMBER(SEARCH("business analy",B22)),"Business Analyst",OR(ISNUMBER(SEARCH("developer",B22)),ISNUMBER(SEARCH("software engineer",B22)),ISNUMBER(SEARCH("programmer",B22))),"Software Developer",ISNUMBER(SEARCH("business development",B22)),"Business Development",ISNUMBER(SEARCH("sales",B22)),"Sales Executive",ISNUMBER(SEARCH("marketing",B22)),"Marketing Executive",OR(ISNUMBER(SEARCH("hr ",B22)),ISNUMBER(SEARCH("recruit",B22)),ISNUMBER(SEARCH("human resource",B22))),"HR / Recruiter",OR(ISNUMBER(SEARCH("account",B22)),ISNUMBER(SEARCH("finance",B22)),ISNUMBER(SEARCH("tax",B22)),ISNUMBER(SEARCH("audit",B22))),"Accountant / Finance",OR(ISNUMBER(SEARCH("customer service",B22)),ISNUMBER(SEARCH("customer support",B22)),ISNUMBER(SEARCH("customer care",B22)),ISNUMBER(SEARCH("voice process",B22)),ISNUMBER(SEARCH("bpo",B22))),"Customer Support",ISNUMBER(SEARCH("engineer",B22)),"Engineer (Technical)",ISNUMBER(SEARCH("manager",B22)),"Manager",OR(ISNUMBER(SEARCH("teacher",B22)),ISNUMBER(SEARCH("trainer",B22)),ISNUMBER(SEARCH("faculty",B22))),"Teacher / Trainer",OR(ISNUMBER(SEARCH("doctor",B22)),ISNUMBER(SEARCH("nurse",B22)),ISNUMBER(SEARCH("medical",B22)),ISNUMBER(SEARCH("pharma",B22)),ISNUMBER(SEARCH("clinical",B22))),"Healthcare",TRUE,"Other") | Q22: =IF(COUNTIFS($B$11:B22,B22,$C$11:C22,C22,$D$11:D22,D22,$L$11:L22,L22)>1,"Duplicate","Unique")
... A444: =Raw_Data!A435 | B444: =PROPER(TRIM(Raw_Data!B435)) | C444: =TRIM(Raw_Data!C435) | D444: =IF(PROPER(TRIM(Raw_Data!D435))="Bangalore","Bengaluru",IF(PROPER(TRIM(Raw_Data!D435))="Gurgaon","Gurugram",IF(OR(PROPER(TRIM(Raw_Data!D435))="New Delhi",PROPER(TRIM(Raw_Data!D435))="Delhi"),"Delhi",PROPER(TRIM(Raw_Data!D435))))) | E444: =Raw_Data!E435 | F444: =IF(TRIM(Raw_Data!F435&"")="","Not Specified",Raw_Data!F435) | G444: =Raw_Data!G435 | H444: =Raw_Data!H435 | I444: =IF(Raw_Data!I435="","",Raw_Data!I435) | J444: =IF(Raw_Data!J435="","",Raw_Data!J435) | K444: =IF(TRIM(Raw_Data!K435&"")="","Not Specified",Raw_Data!K435) | L444: =Raw_Data!L435 | M444: =IF(OR(I444="",J444=""),"",(I444+J444)/2) | N444: =IF(OR(I444="",J444=""),"",J444-I444) | O444: =TEXT(L444,"mmm-yyyy") | P444: =_xlfn.IFS(ISNUMBER(SEARCH("data analy",B444)),"Data Analyst",ISNUMBER(SEARCH("business analy",B444)),"Business Analyst",OR(ISNUMBER(SEARCH("developer",B444)),ISNUMBER(SEARCH("software engineer",B444)),ISNUMBER(SEARCH("programmer",B444))),"Software Developer",ISNUMBER(SEARCH("business development",B444)),"Business Development",ISNUMBER(SEARCH("sales",B444)),"Sales Executive",ISNUMBER(SEARCH("marketing",B444)),"Marketing Executive",OR(ISNUMBER(SEARCH("hr ",B444)),ISNUMBER(SEARCH("recruit",B444)),ISNUMBER(SEARCH("human resource",B444))),"HR / Recruiter",OR(ISNUMBER(SEARCH("account",B444)),ISNUMBER(SEARCH("finance",B444)),ISNUMBER(SEARCH("tax",B444)),ISNUMBER(SEARCH("audit",B444))),"Accountant / Finance",OR(ISNUMBER(SEARCH("customer service",B444)),ISNUMBER(SEARCH("customer support",B444)),ISNUMBER(SEARCH("customer care",B444)),ISNUMBER(SEARCH("voice process",B444)),ISNUMBER(SEARCH("bpo",B444))),"Customer Support",ISNUMBER(SEARCH("engineer",B444)),"Engineer (Technical)",ISNUMBER(SEARCH("manager",B444)),"Manager",OR(ISNUMBER(SEARCH("teacher",B444)),ISNUMBER(SEARCH("trainer",B444)),ISNUMBER(SEARCH("faculty",B444))),"Teacher / Trainer",OR(ISNUMBER(SEARCH("doctor",B444)),ISNUMBER(SEARCH("nurse",B444)),ISNUMBER(SEARCH("medical",B444)),ISNUMBER(SEARCH("pharma",B444)),ISNUMBER(SEARCH("clinical",B444))),"Healthcare",TRUE,"Other") | Q444: =IF(COUNTIFS($B$11:B444,B444,$C$11:C444,C444,$D$11:D444,D444,$L$11:L444,L444)>1,"Duplicate","Unique")

Sheet Analysis
A1: Analysis — Pivot-Style Summary Tables (COUNTIFS / SUMIFS / AVERAGEIFS)
A2: These tables recreate what an Excel PivotTable would show, but are built with formulas so every number stays visible and easy to explain. All tables exclude duplicate postings (Duplicate_Flag = Unique) and respond live to the 5 filter dropdowns on the Dashboard sheet.
A3: Jobs by Job Role | D3: Jobs by Location (Top 20) | G3: Jobs by Industry
A4: Job_Role | B4: Job_Count | D4: Location | E4: Job_Count | G4: Industry | H4: Job_Count
A5: Sales Executive | B5: =COUNTIFS(NR_RoleCategory,A5,NR_RoleCategory,IF(NR_F_Role="All","*",NR_F_Role),NR_Location,IF(NR_F_Loc="All","*",NR_F_Loc),NR_ExpLevel,IF(NR_F_Exp="All","*",NR_F_Exp),NR_WorkMode,IF(NR_F_WM="All","*",NR_F_WM),NR_Industry,IF(NR_F_Ind="All","*",NR_F_Ind),NR_DupFlag,"Unique") | D5: Bengaluru | E5: =COUNTIFS(NR_Location,D5,NR_RoleCategory,IF(NR_F_Role="All","*",NR_F_Role),NR_Location,IF(NR_F_Loc="All","*",NR_F_Loc),NR_ExpLevel,IF(NR_F_Exp="All","*",NR_F_Exp),NR_WorkMode,IF(NR_F_WM="All","*",NR_F_WM),NR_Industry,IF(NR_F_Ind="All","*",NR_F_Ind),NR_DupFlag,"Unique") | G5: IT / Software | H5: =COUNTIFS(NR_Industry,G5,NR_RoleCategory,IF(NR_F_Role="All","*",NR_F_Role),NR_Location,IF(NR_F_Loc="All","*",NR_F_Loc),NR_ExpLevel,IF(NR_F_Exp="All","*",NR_F_Exp),NR_WorkMode,IF(NR_F_WM="All","*",NR_F_WM),NR_Industry,IF(NR_F_Ind="All","*",NR_F_Ind),NR_DupFlag,"Unique")
A6: Engineer (Technical) | B6: =COUNTIFS(NR_RoleCategory,A6,NR_RoleCategory,IF(NR_F_Role="All","*",NR_F_Role),NR_Location,IF(NR_F_Loc="All","*",NR_F_Loc),NR_ExpLevel,IF(NR_F_Exp="All","*",NR_F_Exp),NR_WorkMode,IF(NR_F_WM="All","*",NR_F_WM),NR_Industry,IF(NR_F_Ind="All","*",NR_F_Ind),NR_DupFlag,"Unique") | D6: Pune | E6: =COUNTIFS(NR_Location,D6,NR_RoleCategory,IF(NR_F_Role="All","*",NR_F_Role),NR_Location,IF(NR_F_Loc="All","*",NR_F_Loc),NR_ExpLevel,IF(NR_F_Exp="All","*",NR_F_Exp),NR_WorkMode,IF(NR_F_WM="All","*",NR_F_WM),NR_Industry,IF(NR_F_Ind="All","*",NR_F_Ind),NR_DupFlag,"Unique") | G6: Other / General Business | H6: =COUNTIFS(NR_Industry,G6,NR_RoleCategory,IF(NR_F_Role="All","*",NR_F_Role),NR_Location,IF(NR_F_Loc="All","*",NR_F_Loc),NR_ExpLevel,IF(NR_F_Exp="All","*",NR_F_Exp),NR_WorkMode,IF(NR_F_WM="All","*",NR_F_WM),NR_Industry,IF(NR_F_Ind="All","*",NR_F_Ind),NR_DupFlag,"Unique")
A7: Manager | B7: =COUNTIFS(NR_RoleCategory,A7,NR_RoleCategory,IF(NR_F_Role="All","*",NR_F_Role),NR_Location,IF(NR_F_Loc="All","*",NR_F_Loc),NR_ExpLevel,IF(NR_F_Exp="All","*",NR_F_Exp),NR_WorkMode,IF(NR_F_WM="All","*",NR_F_WM),NR_Industry,IF(NR_F_Ind="All","*",NR_F_Ind),NR_DupFlag,"Unique") | D7: Hyderabad | E7: =COUNTIFS(NR_Location,D7,NR_RoleCategory,IF(NR_F_Role="All","*",NR_F_Role),NR_Location,IF(NR_F_Loc="All","*",NR_F_Loc),NR_ExpLevel,IF(NR_F_Exp="All","*",NR_F_Exp),NR_WorkMode,IF(NR_F_WM="All","*",NR_F_WM),NR_Industry,IF(NR_F_Ind="All","*",NR_F_Ind),NR_DupFlag,"Unique") | G7: BFSI (Banking/Finance/Insurance) | H7: =COUNTIFS(NR_Industry,G7,NR_RoleCategory,IF(NR_F_Role="All","*",NR_F_Role),NR_Location,IF(NR_F_Loc="All","*",NR_F_Loc),NR_ExpLevel,IF(NR_F_Exp="All","*",NR_F_Exp),NR_WorkMode,IF(NR_F_WM="All","*",NR_F_WM),NR_Industry,IF(NR_F_Ind="All","*",NR_F_Ind),NR_DupFlag,"Unique")
A8: Software Developer | B8: =COUNTIFS(NR_RoleCategory,A8,NR_RoleCategory,IF(NR_F_Role="All","*",NR_F_Role),NR_Location,IF(NR_F_Loc="All","*",NR_F_Loc),NR_ExpLevel,IF(NR_F_Exp="All","*",NR_F_Exp),NR_WorkMode,IF(NR_F_WM="All","*",NR_F_WM),NR_Industry,IF(NR_F_Ind="All","*",NR_F_Ind),NR_DupFlag,"Unique") | D8: Chennai | E8: =COUNTIFS(NR_Location,D8,NR_RoleCategory,IF(NR_F_Role="All","*",NR_F_Role),NR_Location,IF(NR_F_Loc="All","*",NR_F_Loc),NR_ExpLevel,IF(NR_F_Exp="All","*",NR_F_Exp),NR_WorkMode,IF(NR_F_WM="All","*",NR_F_WM),NR_Industry,IF(NR_F_Ind="All","*",NR_F_Ind),NR_DupFlag,"Unique") | G8: Manufacturing & Engineering | H8: =COUNTIFS(NR_Industry,G8,NR_RoleCategory,IF(NR_F_Role="All","*",NR_F_Role),NR_Location,IF(NR_F_Loc="All","*",NR_F_Loc),NR_ExpLevel,IF(NR_F_Exp="All","*",NR_F_Exp),NR_WorkMode,IF(NR_F_WM="All","*",NR_F_WM),NR_Industry,IF(NR_F_Ind="All","*",NR_F_Ind),NR_DupFlag,"Unique")
A9: Accountant / Finance | B9: =COUNTIFS(NR_RoleCategory,A9,NR_RoleCategory,IF(NR_F_Role="All","*",NR_F_Role),NR_Location,IF(NR_F_Loc="All","*",NR_F_Loc),NR_ExpLevel,IF(NR_F_Exp="All","*",NR_F_Exp),NR_WorkMode,IF(NR_F_WM="All","*",NR_F_WM),NR_Industry,IF(NR_F_Ind="All","*",NR_F_Ind),NR_DupFlag,"Unique") | D9: Gurugram | E9: =COUNTIFS(NR_Location,D9,NR_RoleCategory,IF(NR_F_Role="All","*",NR_F_Role),NR_Location,IF(NR_F_Loc="All","*",NR_F_Loc),NR_ExpLevel,IF(NR_F_Exp="All","*",NR_F_Exp),NR_WorkMode,IF(NR_F_WM="All","*",NR_F_WM),NR_Industry,IF(NR_F_Ind="All","*",NR_F_Ind),NR_DupFlag,"Unique") | G9: Marketing & Advertising | H9: =COUNTIFS(NR_Industry,G9,NR_RoleCategory,IF(NR_F_Role="All","*",NR_F_Role),NR_Location,IF(NR_F_Loc="All","*",NR_F_Loc),NR_ExpLevel,IF(NR_F_Exp="All","*",NR_F_Exp),NR_WorkMode,IF(NR_F_WM="All","*",NR_F_WM),NR_Industry,IF(NR_F_Ind="All","*",NR_F_Ind),NR_DupFlag,"Unique")
A10: Customer Support | B10: =COUNTIFS(NR_RoleCategory,A10,NR_RoleCategory,IF(NR_F_Role="All","*",NR_F_Role),NR_Location,IF(NR_F_Loc="All","*",NR_F_Loc),NR_ExpLevel,IF(NR_F_Exp="All","*",NR_F_Exp),NR_WorkMode,IF(NR_F_WM="All","*",NR_F_WM),NR_Industry,IF(NR_F_Ind="All","*",NR_F_Ind),NR_DupFlag,"Unique") | D10: Mumbai | E10: =COUNTIFS(NR_Location,D10,NR_RoleCategory,IF(NR_F_Role="All","*",NR_F_Role),NR_Location,IF(NR_F_Loc="All","*",NR_F_Loc),NR_ExpLevel,IF(NR_F_Exp="All","*",NR_F_Exp),NR_WorkMode,IF(NR_F_WM="All","*",NR_F_WM),NR_Industry,IF(NR_F_Ind="All","*",NR_F_Ind),NR_DupFlag,"Unique") | G10: Customer Service & BPO | H10: =COUNTIFS(NR_Industry,G10,NR_RoleCategory,IF(NR_F_Role="All","*",NR_F_Role),NR_Location,IF(NR_F_Loc="All","*",NR_F_Loc),NR_ExpLevel,IF(NR_F_Exp="All","*",NR_F_Exp),NR_WorkMode,IF(NR_F_WM="All","*",NR_F_WM),NR_Industry,IF(NR_F_Ind="All","*",NR_F_Ind),NR_DupFlag,"Unique")
A11: HR / Recruiter | B11: =COUNTIFS(NR_RoleCategory,A11,NR_RoleCategory,IF(NR_F_Role="All","*",NR_F_Role),NR_Location,IF(NR_F_Loc="All","*",NR_F_Loc),NR_ExpLevel,IF(NR_F_Exp="All","*",NR_F_Exp),NR_WorkMode,IF(NR_F_WM="All","*",NR_F_WM),NR_Industry,IF(NR_F_Ind="All","*",NR_F_Ind),NR_DupFlag,"Unique") | D11: Noida | E11: =COUNTIFS(NR_Location,D11,NR_RoleCategory,IF(NR_F_Role="All","*",NR_F_Role),NR_Location,IF(NR_F_Loc="All","*",NR_F_Loc),NR_ExpLevel,IF(NR_F_Exp="All","*",NR_F_Exp),NR_WorkMode,IF(NR_F_WM="All","*",NR_F_WM),NR_Industry,IF(NR_F_Ind="All","*",NR_F_Ind),NR_DupFlag,"Unique") | G11: Sales & Business Development | H11: =COUNTIFS(NR_Industry,G11,NR_RoleCategory,IF(NR_F_Role="All","*",NR_F_Role),NR_Location,IF(NR_F_Loc="All","*",NR_F_Loc),NR_ExpLevel,IF(NR_F_Exp="All","*",NR_F_Exp),NR_WorkMode,IF(NR_F_WM="All","*",NR_F_WM),NR_Industry,IF(NR_F_Ind="All","*",NR_F_Ind),NR_DupFlag,"Unique")
A12: Business Development | B12: =COUNTIFS(NR_RoleCategory,A12,NR_RoleCategory,IF(NR_F_Role="All","*",NR_F_Role),NR_Location,IF(NR_F_Loc="All","*",NR_F_Loc),NR_ExpLevel,IF(NR_F_Exp="All","*",NR_F_Exp),NR_WorkMode,IF(NR_F_WM="All","*",NR_F_WM),NR_Industry,IF(NR_F_Ind="All","*",NR_F_Ind),NR_DupFlag,"Unique") | D12: Ahmedabad | E12: =COUNTIFS(NR_Location,D12,NR_RoleCategory,IF(NR_F_Role="All","*",NR_F_Role),NR_Location,IF(NR_F_Loc="All","*",NR_F_Loc),NR_ExpLevel,IF(NR_F_Exp="All","*",NR_F_Exp),NR_WorkMode,IF(NR_F_WM="All","*",NR_F_WM),NR_Industry,IF(NR_F_Ind="All","*",NR_F_Ind),NR_DupFlag,"Unique") | G12: Healthcare & Pharma | H12: =COUNTIFS(NR_Industry,G12,NR_RoleCategory,IF(NR_F_Role="All","*",NR_F_Role),NR_Location,IF(NR_F_Loc="All","*",NR_F_Loc),NR_ExpLevel,IF(NR_F_Exp="All","*",NR_F_Exp),NR_WorkMode,IF(NR_F_WM="All","*",NR_F_WM),NR_Industry,IF(NR_F_Ind="All","*",NR_F_Ind),NR_DupFlag,"Unique")
A13: Teacher / Trainer | B13: =COUNTIFS(NR_RoleCategory,A13,NR_RoleCategory,IF(NR_F_Role="All","*",NR_F_Role),NR_Location,IF(NR_F_Loc="All","*",NR_F_Loc),NR_ExpLevel,IF(NR_F_Exp="All","*",NR_F_Exp),NR_WorkMode,IF(NR_F_WM="All","*",NR_F_WM),NR_Industry,IF(NR_F_Ind="All","*",NR_F_Ind),NR_DupFlag,"Unique") | D13: Thane | E13: =COUNTIFS(NR_Location,D13,NR_RoleCategory,IF(NR_F_Role="All","*",NR_F_Role),NR_Location,IF(NR_F_Loc="All","*",NR_F_Loc),NR_ExpLevel,IF(NR_F_Exp="All","*",NR_F_Exp),NR_WorkMode,IF(NR_F_WM="All","*",NR_F_WM),NR_Industry,IF(NR_F_Ind="All","*",NR_F_Ind),NR_DupFlag,"Unique") | G13: Education & Training | H13: =COUNTIFS(NR_Industry,G13,NR_RoleCategory,IF(NR_F_Role="All","*",NR_F_Role),NR_Location,IF(NR_F_Loc="All","*",NR_F_Loc),NR_ExpLevel,IF(NR_F_Exp="All","*",NR_F_Exp),NR_WorkMode,IF(NR_F_WM="All","*",NR_F_WM),NR_Industry,IF(NR_F_Ind="All","*",NR_F_Ind),NR_DupFlag,"Unique")
A14: Marketing Executive | B14: =COUNTIFS(NR_RoleCategory,A14,NR_RoleCategory,IF(NR_F_Role="All","*",NR_F_Role),NR_Location,IF(NR_F_Loc="All","*",NR_F_Loc),NR_ExpLevel,IF(NR_F_Exp="All","*",NR_F_Exp),NR_WorkMode,IF(NR_F_WM="All","*",NR_F_WM),NR_Industry,IF(NR_F_Ind="All","*",NR_F_Ind),NR_DupFlag,"Unique") | D14: Remote | E14: =COUNTIFS(NR_Location,D14,NR_RoleCategory,IF(NR_F_Role="All","*",NR_F_Role),NR_Location,IF(NR_F_Loc="All","*",NR_F_Loc),NR_ExpLevel,IF(NR_F_Exp="All","*",NR_F_Exp),NR_WorkMode,IF(NR_F_WM="All","*",NR_F_WM),NR_Industry,IF(NR_F_Ind="All","*",NR_F_Ind),NR_DupFlag,"Unique") | G14: HR & Staffing | H14: =COUNTIFS(NR_Industry,G14,NR_RoleCategory,IF(NR_F_Role="All","*",NR_F_Role),NR_Location,IF(NR_F_Loc="All","*",NR_F_Loc),NR_ExpLevel,IF(NR_F_Exp="All","*",NR_F_Exp),NR_WorkMode,IF(NR_F_WM="All","*",NR_F_WM),NR_Industry,IF(NR_F_Ind="All","*",NR_F_Ind),NR_DupFlag,"Unique")
A15: Healthcare | B15: =COUNTIFS(NR_RoleCategory,A15,NR_RoleCategory,IF(NR_F_Role="All","*",NR_F_Role),NR_Location,IF(NR_F_Loc="All","*",NR_F_Loc),NR_ExpLevel,IF(NR_F_Exp="All","*",NR_F_Exp),NR_WorkMode,IF(NR_F_WM="All","*",NR_F_WM),NR_Industry,IF(NR_F_Ind="All","*",NR_F_Ind),NR_DupFlag,"Unique") | D15: Kolkata | E15: =COUNTIFS(NR_Location,D15,NR_RoleCategory,IF(NR_F_Role="All","*",NR_F_Role),NR_Location,IF(NR_F_Loc="All","*",NR_F_Loc),NR_ExpLevel,IF(NR_F_Exp="All","*",NR_F_Exp),NR_WorkMode,IF(NR_F_WM="All","*",NR_F_WM),NR_Industry,IF(NR_F_Ind="All","*",NR_F_Ind),NR_DupFlag,"Unique") | G15: Logistics & Supply Chain | H15: =COUNTIFS(NR_Industry,G15,NR_RoleCategory,IF(NR_F_Role="All","*",NR_F_Role),NR_Location,IF(NR_F_Loc="All","*",NR_F_Loc),NR_ExpLevel,IF(NR_F_Exp="All","*",NR_F_Exp),NR_WorkMode,IF(NR_F_WM="All","*",NR_F_WM),NR_Industry,IF(NR_F_Ind="All","*",NR_F_Ind),NR_DupFlag,"Unique")
A16: Data Analyst | B16: =COUNTIFS(NR_RoleCategory,A16,NR_RoleCategory,IF(NR_F_Role="All","*",NR_F_Role),NR_Location,IF(NR_F_Loc="All","*",NR_F_Loc),NR_ExpLevel,IF(NR_F_Exp="All","*",NR_F_Exp),NR_WorkMode,IF(NR_F_WM="All","*",NR_F_WM),NR_Industry,IF(NR_F_Ind="All","*",NR_F_Ind),NR_DupFlag,"Unique") | D16: Chandigarh | E16: =COUNTIFS(NR_Location,D16,NR_RoleCategory,IF(NR_F_Role="All","*",NR_F_Role),NR_Location,IF(NR_F_Loc="All","*",NR_F_Loc),NR_ExpLevel,IF(NR_F_Exp="All","*",NR_F_Exp),NR_WorkMode,IF(NR_F_WM="All","*",NR_F_WM),NR_Industry,IF(NR_F_Ind="All","*",NR_F_Ind),NR_DupFlag,"Unique") | G16: Real Estate & Construction | H16: =COUNTIFS(NR_Industry,G16,NR_RoleCategory,IF(NR_F_Role="All","*",NR_F_Role),NR_Location,IF(NR_F_Loc="All","*",NR_F_Loc),NR_ExpLevel,IF(NR_F_Exp="All","*",NR_F_Exp),NR_WorkMode,IF(NR_F_WM="All","*",NR_F_WM),NR_Industry,IF(NR_F_Ind="All","*",NR_F_Ind),NR_DupFlag,"Unique")
A17: Other | B17: =COUNTIFS(NR_RoleCategory,A17,NR_RoleCategory,IF(NR_F_Role="All","*",NR_F_Role),NR_Location,IF(NR_F_Loc="All","*",NR_F_Loc),NR_ExpLevel,IF(NR_F_Exp="All","*",NR_F_Exp),NR_WorkMode,IF(NR_F_WM="All","*",NR_F_WM),NR_Industry,IF(NR_F_Ind="All","*",NR_F_Ind),NR_DupFlag,"Unique") | D17: Mysuru | E17: =COUNTIFS(NR_Location,D17,NR_RoleCategory,IF(NR_F_Role="All","*",NR_F_Role),NR_Location,IF(NR_F_Loc="All","*",NR_F_Loc),NR_ExpLevel,IF(NR_F_Exp="All","*",NR_F_Exp),NR_WorkMode,IF(NR_F_WM="All","*",NR_F_WM),NR_Industry,IF(NR_F_Ind="All","*",NR_F_Ind),NR_DupFlag,"Unique") | G17: Media & Entertainment | H17: =COUNTIFS(NR_Industry,G17,NR_RoleCategory,IF(NR_F_Role="All","*",NR_F_Role),NR_Location,IF(NR_F_Loc="All","*",NR_F_Loc),NR_ExpLevel,IF(NR_F_Exp="All","*",NR_F_Exp),NR_WorkMode,IF(NR_F_WM="All","*",NR_F_WM),NR_Industry,IF(NR_F_Ind="All","*",NR_F_Ind),NR_DupFlag,"Unique")
D18: Surat | E18: =COUNTIFS(NR_Location,D18,NR_RoleCategory,IF(NR_F_Role="All","*",NR_F_Role),NR_Location,IF(NR_F_Loc="All","*",NR_F_Loc),NR_ExpLevel,IF(NR_F_Exp="All","*",NR_F_Exp),NR_WorkMode,IF(NR_F_WM="All","*",NR_F_WM),NR_Industry,IF(NR_F_Ind="All","*",NR_F_Ind),NR_DupFlag,"Unique") | G18: Telecom | H18: =COUNTIFS(NR_Industry,G18,NR_RoleCategory,IF(NR_F_Role="All","*",NR_F_Role),NR_Location,IF(NR_F_Loc="All","*",NR_F_Loc),NR_ExpLevel,IF(NR_F_Exp="All","*",NR_F_Exp),NR_WorkMode,IF(NR_F_WM="All","*",NR_F_WM),NR_Industry,IF(NR_F_Ind="All","*",NR_F_Ind),NR_DupFlag,"Unique")
D19: Jaipur | E19: =COUNTIFS(NR_Location,D19,NR_RoleCategory,IF(NR_F_Role="All","*",NR_F_Role),NR_Location,IF(NR_F_Loc="All","*",NR_F_Loc),NR_ExpLevel,IF(NR_F_Exp="All","*",NR_F_Exp),NR_WorkMode,IF(NR_F_WM="All","*",NR_F_WM),NR_Industry,IF(NR_F_Ind="All","*",NR_F_Ind),NR_DupFlag,"Unique") | G19: Hospitality & Travel | H19: =COUNTIFS(NR_Industry,G19,NR_RoleCategory,IF(NR_F_Role="All","*",NR_F_Role),NR_Location,IF(NR_F_Loc="All","*",NR_F_Loc),NR_ExpLevel,IF(NR_F_Exp="All","*",NR_F_Exp),NR_WorkMode,IF(NR_F_WM="All","*",NR_F_WM),NR_Industry,IF(NR_F_Ind="All","*",NR_F_Ind),NR_DupFlag,"Unique")
D20: Mumbai Suburban | E20: =COUNTIFS(NR_Location,D20,NR_RoleCategory,IF(NR_F_Role="All","*",NR_F_Role),NR_Location,IF(NR_F_Loc="All","*",NR_F_Loc),NR_ExpLevel,IF(NR_F_Exp="All","*",NR_F_Exp),NR_WorkMode,IF(NR_F_WM="All","*",NR_F_WM),NR_Industry,IF(NR_F_Ind="All","*",NR_F_Ind),NR_DupFlag,"Unique") | G20: Retail & E-commerce | H20: =COUNTIFS(NR_Industry,G20,NR_RoleCategory,IF(NR_F_Role="All","*",NR_F_Role),NR_Location,IF(NR_F_Loc="All","*",NR_F_Loc),NR_ExpLevel,IF(NR_F_Exp="All","*",NR_F_Exp),NR_WorkMode,IF(NR_F_WM="All","*",NR_F_WM),NR_Industry,IF(NR_F_Ind="All","*",NR_F_Ind),NR_DupFlag,"Unique")
D21: Udaipur | E21: =COUNTIFS(NR_Location,D21,NR_RoleCategory,IF(NR_F_Role="All","*",NR_F_Role),NR_Location,IF(NR_F_Loc="All","*",NR_F_Loc),NR_ExpLevel,IF(NR_F_Exp="All","*",NR_F_Exp),NR_WorkMode,IF(NR_F_WM="All","*",NR_F_WM),NR_Industry,IF(NR_F_Ind="All","*",NR_F_Ind),NR_DupFlag,"Unique")
D22: Nashik | E22: =COUNTIFS(NR_Location,D22,NR_RoleCategory,IF(NR_F_Role="All","*",NR_F_Role),NR_Location,IF(NR_F_Loc="All","*",NR_F_Loc),NR_ExpLevel,IF(NR_F_Exp="All","*",NR_F_Exp),NR_WorkMode,IF(NR_F_WM="All","*",NR_F_WM),NR_Industry,IF(NR_F_Ind="All","*",NR_F_Ind),NR_DupFlag,"Unique")
D23: Navi Mumbai | E23: =COUNTIFS(NR_Location,D23,NR_RoleCategory,IF(NR_F_Role="All","*",NR_F_Role),NR_Location,IF(NR_F_Loc="All","*",NR_F_Loc),NR_ExpLevel,IF(NR_F_Exp="All","*",NR_F_Exp),NR_WorkMode,IF(NR_F_WM="All","*",NR_F_WM),NR_Industry,IF(NR_F_Ind="All","*",NR_F_Ind),NR_DupFlag,"Unique")
D24: Vasai | E24: =COUNTIFS(NR_Location,D24,NR_RoleCategory,IF(NR_F_Role="All","*",NR_F_Role),NR_Location,IF(NR_F_Loc="All","*",NR_F_Loc),NR_ExpLevel,IF(NR_F_Exp="All","*",NR_F_Exp),NR_WorkMode,IF(NR_F_WM="All","*",NR_F_WM),NR_Industry,IF(NR_F_Ind="All","*",NR_F_Ind),NR_DupFlag,"Unique")
A27: Jobs by Experience Level | D27: Jobs by Work Mode | G27: Average Salary by Experience Level (Lacs PA)
A28: Experience_Level | B28: Job_Count | D28: Work_Mode | E28: Job_Count | G28: Experience_Level | H28: Avg_Salary
A29: Entry Level (0-2 yrs) | B29: =COUNTIFS(NR_ExpLevel,A29,NR_RoleCategory,IF(NR_F_Role="All","*",NR_F_Role),NR_Location,IF(NR_F_Loc="All","*",NR_F_Loc),NR_ExpLevel,IF(NR_F_Exp="All","*",NR_F_Exp),NR_WorkMode,IF(NR_F_WM="All","*",NR_F_WM),NR_Industry,IF(NR_F_Ind="All","*",NR_F_Ind),NR_DupFlag,"Unique") | D29: On-site | E29: =COUNTIFS(NR_WorkMode,D29,NR_RoleCategory,IF(NR_F_Role="All","*",NR_F_Role),NR_Location,IF(NR_F_Loc="All","*",NR_F_Loc),NR_ExpLevel,IF(NR_F_Exp="All","*",NR_F_Exp),NR_WorkMode,IF(NR_F_WM="All","*",NR_F_WM),NR_Industry,IF(NR_F_Ind="All","*",NR_F_Ind),NR_DupFlag,"Unique") | G29: Entry Level (0-2 yrs) | H29: =IFERROR(AVERAGEIFS(NR_AvgSalary,NR_ExpLevel,G29,NR_RoleCategory,IF(NR_F_Role="All","*",NR_F_Role),NR_Location,IF(NR_F_Loc="All","*",NR_F_Loc),NR_ExpLevel,IF(NR_F_Exp="All","*",NR_F_Exp),NR_WorkMode,IF(NR_F_WM="All","*",NR_F_WM),NR_Industry,IF(NR_F_Ind="All","*",NR_F_Ind),NR_DupFlag,"Unique"),"n/a")
